Loaded dependency [numpy/1.22.3-python-3.9.11-openblas-0.3.19]: openblas/0.3.19
Loaded dependency [python3/3.9.11]: gcc/10.3.0-binutils-2.36.1
Loaded dependency [numpy/1.22.3-python-3.9.11-openblas-0.3.19]: python3/3.9.11
Loaded dependency [scipy/1.7.3-python-3.9.11]: numpy/1.22.3-python-3.9.11-openblas-0.3.19
Loaded module: scipy/1.7.3-python-3.9.11

Loading scipy/1.7.3-python-3.9.11
  Loading requirement: openblas/0.3.19 gcc/10.3.0-binutils-2.36.1 python3/3.9.11
    numpy/1.22.3-python-3.9.11-openblas-0.3.19
Loaded module: cuda/11.7
/work3/s204117/News-Recommendations/DataIterator.py:138: SettingWithCopyWarning: 
A value is trying to be set on a copy of a slice from a DataFrame

See the caveats in the documentation: https://pandas.pydata.org/pandas-docs/stable/user_guide/indexing.html#returning-a-view-versus-a-copy
  self.user_data['history_length'][self.user_data['history_length'] > 50] = 50
/work3/s204117/News-Recommendations/DataIterator.py:138: SettingWithCopyWarning: 
A value is trying to be set on a copy of a slice from a DataFrame

See the caveats in the documentation: https://pandas.pydata.org/pandas-docs/stable/user_guide/indexing.html#returning-a-view-versus-a-copy
  self.user_data['history_length'][self.user_data['history_length'] > 50] = 50
Traceback (most recent call last):
  File "/work3/s204117/News-Recommendations/TrainRevamped.py", line 115, in <module>
    user_id, history_title, history_abstract, history_length, impressions_title, impressions_abstract, impressions_length, labels, n_positive = next(DataIterators)
  File "/work3/s204117/News-Recommendations/venv_1/lib/python3.9/site-packages/torch/utils/data/dataloader.py", line 628, in __next__
    data = self._next_data()
  File "/work3/s204117/News-Recommendations/venv_1/lib/python3.9/site-packages/torch/utils/data/dataloader.py", line 671, in _next_data
    data = self._dataset_fetcher.fetch(index)  # may raise StopIteration
  File "/work3/s204117/News-Recommendations/venv_1/lib/python3.9/site-packages/torch/utils/data/_utils/fetch.py", line 58, in fetch
    data = [self.dataset[idx] for idx in possibly_batched_index]
  File "/work3/s204117/News-Recommendations/venv_1/lib/python3.9/site-packages/torch/utils/data/_utils/fetch.py", line 58, in <listcomp>
    data = [self.dataset[idx] for idx in possibly_batched_index]
  File "/work3/s204117/News-Recommendations/DataIterator.py", line 197, in __getitem__
    impressions_title = [self.news_data.iloc[news_id]['title_encode'] for news_id in impressions]
  File "/work3/s204117/News-Recommendations/DataIterator.py", line 197, in <listcomp>
    impressions_title = [self.news_data.iloc[news_id]['title_encode'] for news_id in impressions]
  File "/work3/s204117/News-Recommendations/venv_1/lib/python3.9/site-packages/pandas/core/indexing.py", line 1073, in __getitem__
    return self._getitem_axis(maybe_callable, axis=axis)
  File "/work3/s204117/News-Recommendations/venv_1/lib/python3.9/site-packages/pandas/core/indexing.py", line 1625, in _getitem_axis
    self._validate_integer(key, axis)
  File "/work3/s204117/News-Recommendations/venv_1/lib/python3.9/site-packages/pandas/core/indexing.py", line 1557, in _validate_integer
    raise IndexError("single positional indexer is out-of-bounds")
IndexError: single positional indexer is out-of-bounds
